{
 "metadata": {
  "language_info": {
   "codemirror_mode": {
    "name": "ipython",
    "version": 3
   },
   "file_extension": ".py",
   "mimetype": "text/x-python",
   "name": "python",
   "nbconvert_exporter": "python",
   "pygments_lexer": "ipython3",
   "version": "3.9.1-final"
  },
  "orig_nbformat": 2,
  "kernelspec": {
   "name": "python3",
   "display_name": "Python 3.9.1 64-bit",
   "metadata": {
    "interpreter": {
     "hash": "4d6401091f6de5a385c299b068c1e85516af19a094234475c31f99f1aabe410a"
    }
   }
  }
 },
 "nbformat": 4,
 "nbformat_minor": 2,
 "cells": [
  {
   "source": [
    "# 05-4 예외처리\n",
    "---\n",
    "때로는 오류를 무시하고 진행하고 싶을 떄 파이썬에서는 try, except를 사용해서 예외적으로 오류를 처리할 수 있다.\n",
    "\n",
    "## 오류는 어떤 때 발생하는가?\n",
    "---\n",
    "어떤 상황에서 어떤 오류가 발생하는지 알아보자. 구문 오류 같은 것이 아닌 실제 프로그램에서 자주 발생하는 오류를 중심으로 확인해보자.  \n",
    "### 1. 디렉터리 안에 없는 파일을 열려고 시도했을 때 발생하는 오류\n",
    "없는 파일을 열려고 하면 FileNotFoundError 가 발생한다."
   ],
   "cell_type": "markdown",
   "metadata": {}
  },
  {
   "cell_type": "code",
   "execution_count": 1,
   "metadata": {},
   "outputs": [
    {
     "output_type": "error",
     "ename": "FileNotFoundError",
     "evalue": "[Errno 2] No such file or directory: 'nonexistenceFile'",
     "traceback": [
      "\u001b[1;31m---------------------------------------------------------------------------\u001b[0m",
      "\u001b[1;31mFileNotFoundError\u001b[0m                         Traceback (most recent call last)",
      "\u001b[1;32m<ipython-input-1-0871bc69dd78>\u001b[0m in \u001b[0;36m<module>\u001b[1;34m\u001b[0m\n\u001b[1;32m----> 1\u001b[1;33m \u001b[0mf\u001b[0m \u001b[1;33m=\u001b[0m \u001b[0mopen\u001b[0m\u001b[1;33m(\u001b[0m\u001b[1;34m\"nonexistenceFile\"\u001b[0m\u001b[1;33m,\u001b[0m \u001b[1;34m'r'\u001b[0m\u001b[1;33m)\u001b[0m\u001b[1;33m\u001b[0m\u001b[1;33m\u001b[0m\u001b[0m\n\u001b[0m",
      "\u001b[1;31mFileNotFoundError\u001b[0m: [Errno 2] No such file or directory: 'nonexistenceFile'"
     ]
    }
   ],
   "source": [
    "f = open(\"nonexistenceFile\", 'r')"
   ]
  },
  {
   "source": [
    "### 2. 0으로 다른 숫자를 나누는 경우에 발생하는 오류\n",
    "이 때는 ZeroDivisionError 가 발생한다."
   ],
   "cell_type": "markdown",
   "metadata": {}
  },
  {
   "cell_type": "code",
   "execution_count": 2,
   "metadata": {},
   "outputs": [
    {
     "output_type": "error",
     "ename": "ZeroDivisionError",
     "evalue": "division by zero",
     "traceback": [
      "\u001b[1;31m---------------------------------------------------------------------------\u001b[0m",
      "\u001b[1;31mZeroDivisionError\u001b[0m                         Traceback (most recent call last)",
      "\u001b[1;32m<ipython-input-2-221068dc2815>\u001b[0m in \u001b[0;36m<module>\u001b[1;34m\u001b[0m\n\u001b[1;32m----> 1\u001b[1;33m \u001b[1;36m4\u001b[0m\u001b[1;33m/\u001b[0m\u001b[1;36m0\u001b[0m\u001b[1;33m\u001b[0m\u001b[1;33m\u001b[0m\u001b[0m\n\u001b[0m",
      "\u001b[1;31mZeroDivisionError\u001b[0m: division by zero"
     ]
    }
   ],
   "source": [
    "4/0"
   ]
  },
  {
   "source": [
    "### 3. 인덱스 오류\n",
    "아래의 오류는 빈번하게 발생하는 오류이다. a는 리스트 \\[1,2,3\\]인데 a\\[4\\]는 a 리스트에서 얻을 수 없는 값이다. 따라서 IndexError가 발생한다. 파이썬은 이런 오류가 발생하면 프로그램을 중단하고 오류 메시지를 보여 준다."
   ],
   "cell_type": "markdown",
   "metadata": {}
  },
  {
   "cell_type": "code",
   "execution_count": 3,
   "metadata": {},
   "outputs": [
    {
     "output_type": "error",
     "ename": "IndexError",
     "evalue": "list index out of range",
     "traceback": [
      "\u001b[1;31m---------------------------------------------------------------------------\u001b[0m",
      "\u001b[1;31mIndexError\u001b[0m                                Traceback (most recent call last)",
      "\u001b[1;32m<ipython-input-3-59fd82b1af02>\u001b[0m in \u001b[0;36m<module>\u001b[1;34m\u001b[0m\n\u001b[0;32m      1\u001b[0m \u001b[0ma\u001b[0m \u001b[1;33m=\u001b[0m \u001b[1;33m[\u001b[0m\u001b[1;36m1\u001b[0m\u001b[1;33m,\u001b[0m\u001b[1;36m2\u001b[0m\u001b[1;33m,\u001b[0m\u001b[1;36m3\u001b[0m\u001b[1;33m]\u001b[0m\u001b[1;33m\u001b[0m\u001b[1;33m\u001b[0m\u001b[0m\n\u001b[1;32m----> 2\u001b[1;33m \u001b[0ma\u001b[0m\u001b[1;33m[\u001b[0m\u001b[1;36m4\u001b[0m\u001b[1;33m]\u001b[0m\u001b[1;33m\u001b[0m\u001b[1;33m\u001b[0m\u001b[0m\n\u001b[0m",
      "\u001b[1;31mIndexError\u001b[0m: list index out of range"
     ]
    }
   ],
   "source": [
    "a = [1,2,3]\n",
    "a[4]"
   ]
  },
  {
   "source": [
    "## 오류 예외 처리 기법\n",
    "---\n",
    "\n",
    "### try, except문\n",
    "오류 처리를 위한 try, except문의 기본 구조는 다음과 같다."
   ],
   "cell_type": "markdown",
   "metadata": {}
  },
  {
   "cell_type": "code",
   "execution_count": null,
   "metadata": {},
   "outputs": [],
   "source": [
    "try:\n",
    "    ...\n",
    "except [발생 오류[as 오류 메시지 변수]]:\n",
    "    ..."
   ]
  },
  {
   "source": [
    "try 블록 수행 중 오류가 발생하면 except 블록이 수행된다. 하지만 try 블록에서 오류가 발생하지 않는다면 except 블록은 수행되지 않는다. 위에서 except 구문을 살펴보면 \\[\\]기호를 사용하는데, 이 기호는 괄호 안의 내용을 생략할 수 있다는 관례 표기법이다. 즉 except 구문은 다양하게 쓰일 수 있는데 그 방법은 다음과 같다.\n",
    "\n",
    "1. try, except만 쓰는 방법  \n",
    "오류 종류에 상관없이 오류가 발생하면 except 블록을 수행한다.\n",
    "> ```\n",
    ">try:\n",
    ">    ...\n",
    ">except:\n",
    ">    ...\n",
    ">```\n",
    "\n",
    "2. 발생 오류만 포함한 except문  \n",
    "오류가 발생했을 때 except문에 미리 정해 놓은 오류 이름과 일치할 때만 except 블록을 수행한다는 뜻이다.\n",
    "> ```\n",
    ">try:\n",
    ">    ...\n",
    ">except 발생 오류:\n",
    ">    ...\n",
    ">```\n",
    "\n",
    "3. 발생 오류와 오류 메시지 변수까지 포함한 except문  \n",
    "이 경우 두 번째 경우에서 오류 메시지의 내용까지 알고 싶을 떄 사용하는 방법이다.\n",
    "> ```\n",
    ">try:\n",
    ">    ...\n",
    ">except 발생 오류 as 오류 메시지 변수:\n",
    ">    ...\n",
    ">```\n",
    "\n",
    "위의 경우에 해당하는 예시를 작성해보자."
   ],
   "cell_type": "markdown",
   "metadata": {}
  },
  {
   "cell_type": "code",
   "execution_count": 4,
   "metadata": {},
   "outputs": [
    {
     "output_type": "stream",
     "name": "stdout",
     "text": [
      "division by zero\n"
     ]
    }
   ],
   "source": [
    "try:\n",
    "    4/0\n",
    "except ZeroDivisionError as e:\n",
    "    print(e)"
   ]
  },
  {
   "source": [
    "이처럼 4를 0으로 나누려고 하면 ZeroDivisionError가 발생하여 except 블록이 실행되고 변수 e에 담기는 오류 메시지를 출력한다."
   ],
   "cell_type": "markdown",
   "metadata": {}
  },
  {
   "source": [
    "### try .. finally\n",
    "try문에는 finally 절을 사용할 수 있다. finally절은 try문 수행 도중 예외 발생 여부에 상관없이 항상 수행된다. 보통 finally 절은 사용한 리소스를 close해야 할 때에 많이 사용한다."
   ],
   "cell_type": "markdown",
   "metadata": {}
  },
  {
   "cell_type": "code",
   "execution_count": null,
   "metadata": {},
   "outputs": [],
   "source": [
    "f = open('foo.txt', 'w')\n",
    "try:\n",
    "    # 무언가를 수행\n",
    "finally:\n",
    "    f.close()"
   ]
  },
  {
   "source": [
    "foo.txt 파일을 쓰기 모드로 연 뒤에 try문을 수행한 후 예외 발생 여부와 상관없이 finally절에서 f.close()로 열린 파일을 닫을 수 있다."
   ],
   "cell_type": "markdown",
   "metadata": {}
  },
  {
   "source": [
    "### 여러 개의 오류 처리하기\n",
    "try문 안에서 여러 개의 오류를 처리하기 위해 다음 구문을 사용한다."
   ],
   "cell_type": "markdown",
   "metadata": {}
  },
  {
   "cell_type": "code",
   "execution_count": null,
   "metadata": {},
   "outputs": [],
   "source": [
    "try:\n",
    "    ...\n",
    "except 발생오류1:\n",
    "    ...\n",
    "except 발생오류2:\n",
    "    ..."
   ]
  },
  {
   "source": [
    "0으로 나누는 오류와 인덱싱 오류를 다음과 같이 처리해보자."
   ],
   "cell_type": "markdown",
   "metadata": {}
  },
  {
   "cell_type": "code",
   "execution_count": 7,
   "metadata": {},
   "outputs": [
    {
     "output_type": "stream",
     "name": "stdout",
     "text": [
      "인덱싱 할 수 없습니다.\n"
     ]
    }
   ],
   "source": [
    "try:\n",
    "    a = [1,2]\n",
    "    print(a[3])\n",
    "    4/0\n",
    "except ZeroDivisionError:\n",
    "    print(\"0으로 나눌 수 없습니다.\")\n",
    "except IndexError:\n",
    "    print(\"인덱싱 할 수 없습니다.\")"
   ]
  },
  {
   "source": [
    "a는 2개의 요솟값을 가지고 있기 때문에 `a[3]`는 `IndexError`를 발생시키므로 \"인덱싱할 수 없습니다.\"라는 문자열이 출력될 것이다. 인덱싱 오류가 먼저 발생했기 때문에 `ZeroDivisionError` 오류는 발생하지 않았다.  \n",
    "\n",
    "오류 메시지는 다음과 같이 가져올 수도 있다."
   ],
   "cell_type": "markdown",
   "metadata": {}
  },
  {
   "cell_type": "code",
   "execution_count": 8,
   "metadata": {},
   "outputs": [
    {
     "output_type": "stream",
     "name": "stdout",
     "text": [
      "list index out of range\n"
     ]
    }
   ],
   "source": [
    "try:\n",
    "    a = [1,2]\n",
    "    print(a[3])\n",
    "    4/0\n",
    "except ZeroDivisionError as e:\n",
    "    print(e)\n",
    "except IndexError as e:\n",
    "    print(e)"
   ]
  },
  {
   "source": [
    "위의 코드를 작성하다가 문득 이런 생각이 들었다. try문에는 오류가 총 2개가 있는데 왜 둘 다 출력할 수는 없을까? 그래서 [stackoverflow에 질문][1]을 올려보았다.  \n",
    "\n",
    "try문의 첫 번째 줄에서 `IndexError`가 발생하면 바로 `IndexError`에 해당하는 `except`로 이동한다. 그래서 `4/0`은 실행 자체가 되지 않은 것이다. 만약 둘 다 에러 메시지를 띄워 주고 싶다면 2개의 서로 다른 try-except 문을 작성해야 하고 그 예시는 다음과 같다.\n",
    "\n",
    "[1]: https://stackoverflow.com/questions/65869448/how-to-print-every-error-using-try-except-in-python"
   ],
   "cell_type": "markdown",
   "metadata": {}
  },
  {
   "cell_type": "code",
   "execution_count": 11,
   "metadata": {},
   "outputs": [
    {
     "output_type": "stream",
     "name": "stdout",
     "text": [
      "list index out of range\ndivision by zero\n"
     ]
    }
   ],
   "source": [
    "try:\n",
    "    a = [1, 2]\n",
    "    print(a[3])\n",
    "except IndexError as e:\n",
    "    print(e)\n",
    "\n",
    "try:\n",
    "    4 / 0\n",
    "except ZeroDivisionError as e:\n",
    "    print(e)"
   ]
  },
  {
   "source": [
    "다음과 같이 `ZeroDivisionError`와 `IndexError`를 함께 처리할 수도 있다."
   ],
   "cell_type": "markdown",
   "metadata": {}
  },
  {
   "cell_type": "code",
   "execution_count": 9,
   "metadata": {},
   "outputs": [
    {
     "output_type": "stream",
     "name": "stdout",
     "text": [
      "list index out of range\n"
     ]
    }
   ],
   "source": [
    "try:\n",
    "    a = [1,2]\n",
    "    print(a[3])\n",
    "    4/0\n",
    "except (ZeroDivisionError, IndexError) as e:\n",
    "    print(e)"
   ]
  },
  {
   "source": [
    "## 오류 회피하기\n",
    "---\n",
    "특정 오류가 발생할 경우 그냥 통과시켜야 할 때가 있다. 다음 예시를 확인해보자. "
   ],
   "cell_type": "markdown",
   "metadata": {}
  },
  {
   "cell_type": "code",
   "execution_count": 10,
   "metadata": {},
   "outputs": [],
   "source": [
    "try:\n",
    "    f = open(\"nonexistenceFile\", 'r')\n",
    "except FileNotFoundError:\n",
    "    pass"
   ]
  },
  {
   "source": [
    "try문 안에서 FileNotFoundError가 발생할 경우 **pass**를 사용해서 오류를 그냥 회피하도록 작성했다."
   ],
   "cell_type": "markdown",
   "metadata": {}
  },
  {
   "source": [
    "## 오류 일부러 발생시키기\n",
    "---\n",
    "종종 오류를 일부러 발생시켜야 할 때도 생긴다. 파이썬은 raise 명령어를 사용해 오류를 강제로 발생시킬 수 있다.  \n",
    "\n",
    "예를 들어 Bird 클래스를 상속받는 자식 클래스는 반드시 fly라는 함수를 구현하도록 만들고 싶은 경우가 있을 수 있다. 다음 예시를 보자."
   ],
   "cell_type": "markdown",
   "metadata": {}
  },
  {
   "cell_type": "code",
   "execution_count": 12,
   "metadata": {},
   "outputs": [],
   "source": [
    "class Bird:\n",
    "    def fly(self):\n",
    "        raise NotImplementedError"
   ]
  },
  {
   "source": [
    "위 예제는 Bird 클래스를 상속받는 자식 클래스는 반드시 fly 함수를 구현해야 한다는 의지를 보여준다. 만약 자식 클래스가 fly함수를 구현하지 않은 상태로 fly 함수를 호출한다면 어떻게 될까?\n",
    "> NotImplementedError는 파이썬 내장 오류로, 반드시 작성해야 하는 부분이 구현되지 않았을 경우 일부러 오류를 발생시키기 위해 사용된다."
   ],
   "cell_type": "markdown",
   "metadata": {}
  },
  {
   "cell_type": "code",
   "execution_count": 13,
   "metadata": {},
   "outputs": [
    {
     "output_type": "error",
     "ename": "NotImplementedError",
     "evalue": "",
     "traceback": [
      "\u001b[1;31m---------------------------------------------------------------------------\u001b[0m",
      "\u001b[1;31mNotImplementedError\u001b[0m                       Traceback (most recent call last)",
      "\u001b[1;32m<ipython-input-13-01256a26320c>\u001b[0m in \u001b[0;36m<module>\u001b[1;34m\u001b[0m\n\u001b[0;32m      3\u001b[0m \u001b[1;33m\u001b[0m\u001b[0m\n\u001b[0;32m      4\u001b[0m \u001b[0meagle\u001b[0m \u001b[1;33m=\u001b[0m \u001b[0mEagle\u001b[0m\u001b[1;33m(\u001b[0m\u001b[1;33m)\u001b[0m\u001b[1;33m\u001b[0m\u001b[1;33m\u001b[0m\u001b[0m\n\u001b[1;32m----> 5\u001b[1;33m \u001b[0meagle\u001b[0m\u001b[1;33m.\u001b[0m\u001b[0mfly\u001b[0m\u001b[1;33m(\u001b[0m\u001b[1;33m)\u001b[0m\u001b[1;33m\u001b[0m\u001b[1;33m\u001b[0m\u001b[0m\n\u001b[0m",
      "\u001b[1;32m<ipython-input-12-e8d1e4453b08>\u001b[0m in \u001b[0;36mfly\u001b[1;34m(self)\u001b[0m\n\u001b[0;32m      1\u001b[0m \u001b[1;32mclass\u001b[0m \u001b[0mBird\u001b[0m\u001b[1;33m:\u001b[0m\u001b[1;33m\u001b[0m\u001b[1;33m\u001b[0m\u001b[0m\n\u001b[0;32m      2\u001b[0m     \u001b[1;32mdef\u001b[0m \u001b[0mfly\u001b[0m\u001b[1;33m(\u001b[0m\u001b[0mself\u001b[0m\u001b[1;33m)\u001b[0m\u001b[1;33m:\u001b[0m\u001b[1;33m\u001b[0m\u001b[1;33m\u001b[0m\u001b[0m\n\u001b[1;32m----> 3\u001b[1;33m         \u001b[1;32mraise\u001b[0m \u001b[0mNotImplementedError\u001b[0m\u001b[1;33m\u001b[0m\u001b[1;33m\u001b[0m\u001b[0m\n\u001b[0m",
      "\u001b[1;31mNotImplementedError\u001b[0m: "
     ]
    }
   ],
   "source": [
    "class Eagle(Bird):\n",
    "    pass\n",
    "\n",
    "eagle = Eagle()\n",
    "eagle.fly()"
   ]
  },
  {
   "source": [
    "Eagle 클래스는 Bird 클래스를 상속받는다. 그런데 Eagle 클래스에서 fly함수를 구현하지 않았기 때문에 Bird 클래스의 fly함수가 호출된다. 그리고 raise문에 의해서 NotImplementedError 가 발생한다.  \n",
    "\n",
    "NotImplementedError가 발생되지 않게 하려면 다음과 같이 Eagle 클래스에 fly함수를 반드시 구현해야 한다."
   ],
   "cell_type": "markdown",
   "metadata": {}
  },
  {
   "cell_type": "code",
   "execution_count": 14,
   "metadata": {},
   "outputs": [
    {
     "output_type": "stream",
     "name": "stdout",
     "text": [
      "very fast\n"
     ]
    }
   ],
   "source": [
    "class Eagle(Bird):\n",
    "    def fly(self):\n",
    "        print(\"very fast\")\n",
    "\n",
    "eagle = Eagle()\n",
    "eagle.fly()"
   ]
  },
  {
   "source": [
    "## 예외 만들기\n",
    "---\n",
    "프로그램 수행 도중 특수한 경우에만 예외 처리를 하기 위해서 종종 예외를 만들어서 사용한다. 예외는 파이썬 내장 클래스인 Exception 클래스를 상속하여 만들 수 있다. 직접 예외를 만들어보자."
   ],
   "cell_type": "markdown",
   "metadata": {}
  },
  {
   "cell_type": "code",
   "execution_count": 15,
   "metadata": {},
   "outputs": [],
   "source": [
    "class MyError(Exception):\n",
    "    pass"
   ]
  },
  {
   "source": [
    "별명을 출력해 주는 함수를 다음과 같이 작성한다."
   ],
   "cell_type": "markdown",
   "metadata": {}
  },
  {
   "cell_type": "code",
   "execution_count": 16,
   "metadata": {},
   "outputs": [],
   "source": [
    "def say_nick(nick):\n",
    "    if nick == 'yee yee ass haircut':\n",
    "        raise MyError()\n",
    "    print(nick)"
   ]
  },
  {
   "cell_type": "code",
   "execution_count": 17,
   "metadata": {},
   "outputs": [
    {
     "output_type": "stream",
     "name": "stdout",
     "text": [
      "Franklin\n"
     ]
    },
    {
     "output_type": "error",
     "ename": "MyError",
     "evalue": "",
     "traceback": [
      "\u001b[1;31m---------------------------------------------------------------------------\u001b[0m",
      "\u001b[1;31mMyError\u001b[0m                                   Traceback (most recent call last)",
      "\u001b[1;32m<ipython-input-17-a07131942fff>\u001b[0m in \u001b[0;36m<module>\u001b[1;34m\u001b[0m\n\u001b[0;32m      1\u001b[0m \u001b[0msay_nick\u001b[0m\u001b[1;33m(\u001b[0m\u001b[1;34m\"Franklin\"\u001b[0m\u001b[1;33m)\u001b[0m\u001b[1;33m\u001b[0m\u001b[1;33m\u001b[0m\u001b[0m\n\u001b[1;32m----> 2\u001b[1;33m \u001b[0msay_nick\u001b[0m\u001b[1;33m(\u001b[0m\u001b[1;34m\"yee yee ass haircut\"\u001b[0m\u001b[1;33m)\u001b[0m\u001b[1;33m\u001b[0m\u001b[1;33m\u001b[0m\u001b[0m\n\u001b[0m",
      "\u001b[1;32m<ipython-input-16-dc24e7a2aea5>\u001b[0m in \u001b[0;36msay_nick\u001b[1;34m(nick)\u001b[0m\n\u001b[0;32m      1\u001b[0m \u001b[1;32mdef\u001b[0m \u001b[0msay_nick\u001b[0m\u001b[1;33m(\u001b[0m\u001b[0mnick\u001b[0m\u001b[1;33m)\u001b[0m\u001b[1;33m:\u001b[0m\u001b[1;33m\u001b[0m\u001b[1;33m\u001b[0m\u001b[0m\n\u001b[0;32m      2\u001b[0m     \u001b[1;32mif\u001b[0m \u001b[0mnick\u001b[0m \u001b[1;33m==\u001b[0m \u001b[1;34m'yee yee ass haircut'\u001b[0m\u001b[1;33m:\u001b[0m\u001b[1;33m\u001b[0m\u001b[1;33m\u001b[0m\u001b[0m\n\u001b[1;32m----> 3\u001b[1;33m         \u001b[1;32mraise\u001b[0m \u001b[0mMyError\u001b[0m\u001b[1;33m(\u001b[0m\u001b[1;33m)\u001b[0m\u001b[1;33m\u001b[0m\u001b[1;33m\u001b[0m\u001b[0m\n\u001b[0m\u001b[0;32m      4\u001b[0m     \u001b[0mprint\u001b[0m\u001b[1;33m(\u001b[0m\u001b[0mnick\u001b[0m\u001b[1;33m)\u001b[0m\u001b[1;33m\u001b[0m\u001b[1;33m\u001b[0m\u001b[0m\n",
      "\u001b[1;31mMyError\u001b[0m: "
     ]
    }
   ],
   "source": [
    "say_nick(\"Franklin\")\n",
    "say_nick(\"yee yee ass haircut\")"
   ]
  },
  {
   "source": [
    "프로그램을 실행해보면 \"Franklin\"이 한 번 출력된 뒤 MyError가 발생한다.  \n",
    "\n",
    "이번에는 예외처리기법을 사용해서 MyError 발생을 예외 처리해보자."
   ],
   "cell_type": "markdown",
   "metadata": {}
  },
  {
   "cell_type": "code",
   "execution_count": 18,
   "metadata": {},
   "outputs": [
    {
     "output_type": "stream",
     "name": "stdout",
     "text": [
      "Franklin\nLamar roasts Franklin\n"
     ]
    }
   ],
   "source": [
    "try:\n",
    "    say_nick(\"Franklin\")\n",
    "    say_nick(\"yee yee ass haircut\")\n",
    "except MyError:\n",
    "    print(\"Lamar roasts Franklin\")"
   ]
  },
  {
   "source": [
    "만약 오류 메시지를 사용하고 싶다면 다음처럼 예외처리를 하면 된다."
   ],
   "cell_type": "markdown",
   "metadata": {}
  },
  {
   "cell_type": "code",
   "execution_count": 19,
   "metadata": {},
   "outputs": [
    {
     "output_type": "stream",
     "name": "stdout",
     "text": [
      "Franklin\n\n"
     ]
    }
   ],
   "source": [
    "try:\n",
    "    say_nick(\"Franklin\")\n",
    "    say_nick(\"yee yee ass haircut\")\n",
    "except MyError as e:\n",
    "    print(e)"
   ]
  },
  {
   "source": [
    "하지만 프로그램을 실행해보면 `print(e)` 로 오류 메시지가 출력되지 않는 것을 확인할 수 있다. 오류 메시지를 출력했을 때 오류 메시지가 보이게 하려면 오류 클래스에 다음과 같은 `__str__` 메서드를 구현해야 한다.  \n",
    "`__str__` 메서드는 `print(e)`처럼 오류 메시지를 print문으로 출력할 경우에 호출되는 메서드이다."
   ],
   "cell_type": "markdown",
   "metadata": {}
  },
  {
   "cell_type": "code",
   "execution_count": 20,
   "metadata": {},
   "outputs": [],
   "source": [
    "class MyError(Exception):\n",
    "    def __str__(self):\n",
    "        return(\"Lamar roasts Franklin\")"
   ]
  },
  {
   "cell_type": "code",
   "execution_count": 21,
   "metadata": {},
   "outputs": [
    {
     "output_type": "stream",
     "name": "stdout",
     "text": [
      "Franklin\nLamar roasts Franklin\n"
     ]
    }
   ],
   "source": [
    "try:\n",
    "    say_nick(\"Franklin\")\n",
    "    say_nick(\"yee yee ass haircut\")\n",
    "except MyError as e:\n",
    "    print(e)"
   ]
  }
 ]
}
